<?xml version="1.0"?>
<!-- Author: Emanuel Fallas Hernandez efallashdez@gmail.com -->
<!-- Published under GNU GPLv3 license -->


<!-- This xacro generates a simple parallel gripper that has variable z position -->
<robot name="thor" xmlns:xacro="http://www.ros.org/wiki/xacro">
  <xacro:arg name="prefix" default=""/>

  <!-- Load URDF XACRO -->
  <xacro:include filename="$(find gripper_description)/urdf/gripper.urdf.xacro"/>

  <xacro:macro name="generate_urdf" params="prefix">
    <xacro:gripper prefix="${prefix}"/>
    
    <link name="world" />
    

    <joint
      name="${prefix}base_prismatic"
      type="prismatic">
      <origin
        xyz="0 0 0.15"
        rpy="0 1.5708 0" />
      <parent link="world"/>
      <child link="${prefix}gripper_base"/>
      <axis
        xyz="-1 0 0" />
      <limit
        lower="0"
        upper="0.1"
        effort="100"
        velocity="1" />
      <dynamics
        damping="0.01" />
    </joint>    

    <transmission name="${prefix}base_trans">
        <type>transmission_interface/SimpleTransmission</type>
        <joint name="${prefix}base_prismatic">
            <hardwareInterface>hardware_interface/EffortJointInterface</hardwareInterface>
        </joint>
        <actuator name="${prefix}base_motor">
            <hardwareInterface>hardware_interface/EffortJointInterface</hardwareInterface>
            <mechanicalReduction>1</mechanicalReduction>
        </actuator>
    </transmission>

    <!-- Gazebo -->
    <gazebo>
        <plugin name="gazebo_ros_control" filename="libgazebo_ros_control.so"/>
    </gazebo>


  </xacro:macro>
  
  <xacro:generate_urdf prefix="$(arg prefix)"/>




</robot>
